Workbook

Sheet Pre-condiciones obligatorias
B2: No. | C2: Descripción | D2: Responsable | E2: Fecha de Finalización
B3: 0 | C3: Segregación de BO por país Crear perfiles para Segmento Multilatino
B4: 1 | C4: Criterios de Alta en Back Office
B5: 2 | C5: Carga de Matriz de Productos y permisos
B6: 3 | C6: Carga de Enumerador de Error
B7: 4 | C7: Disponibiliad de Core
B8: 5 | C8: Migración de Destinos Autorizados

Sheet Contenido
A1: P | B1: Estado | C1: Responsable | D1: Observaciones | E1: Todos | F1: Colombia | G1: Panama | H1: Costa Rica | I1: Honduras | J1: El Salvador | K1: Miami | L1: Total
A2: HU001_PER - Single sign on - SSO | B2: Entregado | C2: Devora | E2: ='HU001_PER - Single sign on - SS'!M2 -> 43 | F2: - | G2: - | H2: - | I2: - | J2: - | K2: - | L2: ='HU001_PER - Single sign on - SS'!M2 -> 43
A3: HU002_PER - Home Módulo Regional | B3: Entregado | C3: Sandra | E3: ='HU002_PER - Home Módulo Regiona'!L2 -> 45 | F3: ='HU001_PER - Single sign on - SS'!M3 -> 9 | G3: - | H3: - | I3: - | J3: - | K3: - | L3: ='HU002_PER - Home Módulo Regiona'!L2 -> 45
A4: HU003_PER - Accesos Rápidos | B4: Entregado | C4: Sandra | E4: ='HU003_PER - Accesos Rápidos'!K3 -> 36 | F4: - | G4: - | H4: - | I4: - | J4: - | K4: - | L4: ='HU003_PER - Accesos Rápidos'!K3 -> 36
A5: HU004_PER - Posición consolidada cuentas de ahorro y corriente | B5: Entregado | C5: Sandra | E5: ='HU004 - Posición Consolidada cu'!M9 -> 23 | F5: ='HU004 - Posición Consolidada cu'!M3 -> 2 | G5: ='HU004 - Posición Consolidada cu'!M4 -> 2 | H5: ='HU004 - Posición Consolidada cu'!M5 -> 2 | I5: ='HU004 - Posición Consolidada cu'!M6 -> 2 | J5: ='HU004 - Posición Consolidada cu'!M7 -> 2 | K5: ='HU004 - Posición Consolidada cu'!M8 -> 2 | L5: ='HU004 - Posición Consolidada cu'!M2 -> 35
A6: HU005_PER - Consulta detallada de cuentas | B6: Entregado | C6: Sandra | E6: ='HU005_PER - Consulta detallada '!M3 -> 45 | F6: ='HU006_PER - Detalle movimiento '!M3 -> 3 | G6: ='HU005_PER - Consulta detallada '!M5 -> 3 | H6: ='HU005_PER - Consulta detallada '!M6 -> 3 | I6: ='HU005_PER - Consulta detallada '!M7 -> 3 | J6: ='HU005_PER - Consulta detallada '!M8 -> 3 | K6: ='HU005_PER - Consulta detallada '!M9 -> 3 | L6: ='HU005_PER - Consulta detallada '!M2 -> 63
A7: HU006_PER - Detalle movimiento de cuenta | B7: Entregado | C7: Sandra | E7: ='HU006_PER - Detalle movimiento '!M9 -> 21 | F7: ='HU006_PER - Detalle movimiento '!M3 -> 3 | G7: ='HU006_PER - Detalle movimiento '!M4 -> 3 | H7: ='HU006_PER - Detalle movimiento '!M5 -> 3 | I7: ='HU006_PER - Detalle movimiento '!M6 -> 3 | J7: ='HU006_PER - Detalle movimiento '!M7 -> 3 | K7: ='HU006_PER - Detalle movimiento '!M8 -> 3 | L7: ='HU006_PER - Detalle movimiento '!M2 -> 39
A8: HU007_PER - Consulta y descarga de extractos (Estados de cuenta) | B8: Entregado | C8: Sandra | E8: ='HU007_PER - Consulta y descarga'!N3 -> 7 | F8: ='HU007_PER - Consulta y descarga'!N9 -> 2 | G8: ='HU007_PER - Consulta y descarga'!N7 -> 2 | H8: ='HU007_PER - Consulta y descarga'!N6 -> 2 | I8: ='HU007_PER - Consulta y descarga'!N5 -> 2 | J8: ='HU007_PER - Consulta y descarga'!N4 -> 2 | K8: ='HU007_PER - Consulta y descarga'!N8 -> 2 | L8: ='HU007_PER - Consulta y descarga'!N2 -> 19
A9: HU008_PER - Módulo de administración Banco | B9: Entregado | C9: Katie | D9: Modificar | E9: ='HU008_PER - Módulo de administr'!M2 -> 135 | F9: - | G9: - | H9: - | I9: - | J9: - | K9: - | L9: ='HU008_PER - Módulo de administr'!M2 -> 135
A10: HU009_PER - Administración cliente / Grupo de Productos | B10: Entregado | C10: Katie | E10: ='HU009_PER - Grupo de Productos'!M2 -> 211 | F10: - | G10: - | H10: - | I10: - | J10: - | K10: - | L10: ='HU009_PER - Grupo de Productos'!M2 -> 211
A11: HU010_PER - Administración cliente / Usuarios | B11: Entregado | C11: Katie | E11: ='HU010_PER - Administración clie'!N2 -> 424 | F11: - | G11: - | H11: - | I11: - | J11: - | K11: - | L11: ='HU010_PER - Administración clie'!N2 -> 424
A12: HU011_PER - Administración cliente / Esquema de Firmas | B12: Entregado | C12: Katie | E12: ='HU011_PER - Esquema de Firmas'!N2 -> 219 | F12: - | G12: - | H12: - | I12: - | J12: - | K12: - | L12: ='HU011_PER - Esquema de Firmas'!N2 -> 219
A13: HU012_PER - Destinos Autorizados CAM | B13: Entregado | C13: Devora | D13: Modificar | E13: ='HU012_PER - Destinos Autorizado'!M3 -> 44 | F13: ='HU012_PER - Destinos Autorizado'!M4 -> 0 | G13: ='HU012_PER - Destinos Autorizado'!M5 -> 14 | H13: ='HU012_PER - Destinos Autorizado'!M6 -> 15 | I13: ='HU012_PER - Destinos Autorizado'!M7 -> 12 | J13: ='HU012_PER - Destinos Autorizado'!M8 -> 6 | K13: ='HU012_PER - Destinos Autorizado'!M9 -> 0 | L13: ='HU012_PER - Destinos Autorizado'!M2 -> 91
A14: HU013_PER - Transferencias Regionales CAM / A Cuentas Propias | B14: Entregado | C14: Sandra | E14: ='HU013_PER - Transferencias Regi'!O6 -> 45 | F14: - | G14: ='HU013_PER - Transferencias Regi'!O2 -> 74 | H14: ='HU013_PER - Transferencias Regi'!O3 -> 76 | I14: ='HU013_PER - Transferencias Regi'!O4 -> 74 | J14: ='HU013_PER - Transferencias Regi'!O5 -> 71 | K14: - | L14: ='HU013_PER - Transferencias Regi'!O1 -> 340
A15: HU014_PER - Transferencias Regionales CAM / A Terceros | B15: Entregado | C15: Devora | D15: Modificar | E15: ='HU014_PER - Transferencias Regi'!L7 -> 20 | F15: - | G15: ='HU014_PER - Transferencias Regi'!L3 -> 63 | H15: ='HU014_PER - Transferencias Regi'!L4 -> 65 | I15: ='HU014_PER - Transferencias Regi'!L5 -> 52 | J15: ='HU014_PER - Transferencias Regi'!L6 -> 45 | K15: - | L15: ='HU014_PER - Transferencias Regi'!L2 -> 245
A16: HU015_PER - Transferencias Regionales CAM / Consultas | B16: Entregado | C16: Fatimita | E16: ='HU015_PER - Transferencias Regi'!M3 -> 25 | F16: - | G16: - | H16: - | I16: - | J16: ='HU015_PER - Transferencias Regi'!M4 -> 1 | K16: - | L16: ='HU015_PER - Transferencias Regi'!M2 -> 26
A17: HU016_PER - Transferencias regionales CAM / Programadas | B17: Entregado | C17: Fatimita | D17: Modificar | E17: ='HU016_PER - Transferencias regi'!M3 -> 50 | F17: - | G17: - | H17: - | I17: - | J17: - | K17: - | L17: ='HU016_PER - Transferencias regi'!M2 -> 50
A18: HU017_PER - Autorizaciones transversal | B18: Entregado | C18: Sandra | E18: ='HU017_PER - Autorizaciones tran'!M9 -> 63 | F18: ='HU017_PER - Autorizaciones tran'!M3 -> 16 | G18: ='HU017_PER - Autorizaciones tran'!M4 -> 2 | H18: ='HU017_PER - Autorizaciones tran'!M5 -> 2 | I18: ='HU017_PER - Autorizaciones tran'!M6 -> 2 | J18: ='HU017_PER - Autorizaciones tran'!M7 -> 1 | K18: ='HU017_PER - Autorizaciones tran'!M8 -> 2 | L18: ='HU017_PER - Autorizaciones tran'!M2 -> 88
A19: HU018_PER - Módulo Autorizaciones | B19: N/A | C19: Katie | E19: ='HU018_PER - Módulo Autorizacion'!M2 -> 101 | F19: - | G19: - | H19: - | I19: - | J19: - | K19: - | L19: ='HU018_PER - Módulo Autorizacion'!M2 -> 101
A20: HU019_PER - Buzón Notificaciones | B20: Entregado | C20: Sandra | E20: ='HU019_PER - Buzón Notificacione'!M3 -> 26 | F20: - | G20: - | H20: - | I20: - | J20: - | K20: - | L20: ='HU019_PER - Buzón Notificacione'!M2 -> 27
A21: HU020_PER - Banners | B21: Entregado | C21: Sandra | E21: ='HU020_PER - Banners'!M3 -> 47 | F21: - | G21: - | H21: - | I21: - | J21: - | K21: - | L21: ='HU020_PER - Banners'!M2 -> 47
A22: HU021_PER - Onboarding MVP PER | B22: N/A | C22: Diego | F22: - | G22: - | H22: - | I22: - | J22: - | K22: -
A23: HU022_PER - Migración Destinos Autorizados | B23: Entregado | C23: Devora | E23: ='HU022_PER - Migración Destinos '!M3 -> 4 | F23: - | G23: - | H23: - | I23: - | J23: - | K23: -
A24: Mensajeria Transversal PER | B24: N/A | E24: Enumerados | F24: - | G24: - | H24: - | I24: - | J24: - | K24: - | L24: ='HU022_PER - Migración Destinos '!M3 -> 4
A25: Camara Transferencias Regionales CAM | B25: N/A | E25: N/A
E26: =SUM(E2:E25) -> 1634 | F26: =SUM(F2:F25) -> 35 | G26: =SUM(G2:G25) -> 163 | H26: =SUM(H2:H25) -> 168 | I26: =SUM(I2:I25) -> 150 | J26: =SUM(J2:J25) -> 134 | K26: =SUM(K2:K25) -> 12 | L26: =SUM(L2:L25) -> 2288
A27: Total de casos a ejecutar por cada país | F27: =SUM(E2,E3,E4,E5,E6,E7,E8,E9,E10,E11,E12,F26) -> 1244 | G27: =SUM($E$26,G26) -> 1797 | H27: =SUM(E26,H26) -> 1802 | I27: =SUM($E$26,I26) -> 1784 | J27: =SUM($E$26,J26) -> 1768 | K27: =SUM(E2,E3,E4,E5,E6,E7,E8,E9,E10,E11,E12,K26) -> 1221
A31: Entregable 1
A32: HU023: Cámara de Compensación
A33: HU024: Destinos Autorizados - Colombia
A34: HU025: Destinos Autorizados - Miami
A35: HU035: Destinos Autorizados Internacionales
A36: HU029: Transferencias Regionales Miami - Cuentas Propias
A37: HU030: Transferencias Regionales Miami - Cuentas a Terceros
A38: HU026: Transferencias Regionales Colombia - A cuentas propias
A39: HU027: Transferencias regionales Colombia - A terceros
A40: HU032: Programar transferencias regionales Miami - Cuentas propias
A41: HU033: Programar Transferencias Regionales Miami - Cuentas a terceros
A42: HU038: Consulta transferencias internacionales
... A52: HU036: Consulta y administración - Destinos Autorizados Internacionales

Sheet HU001_PER - Single sign on - SS
A1: Nomenclatura | B1: Requerimiento | C1: Título | D1: Precondición | E1: Descripción | F1: Resultado | G1: Responsable
A2: CP01 | B2: SSO | C2: No se visualice en el menú de Mis Productos la opción de Módulo Regional | D2: El usuario no debe estar marcado en Control Center Banca el Línea como usuarios Multilatino | E2: 1.Ingresar el usuario de Banca en línea de HN,PA,CR,SV,CO,MI 2.Seleccionar Empresa a utilizar 3.Ingresar en la posición consolidada 4.Validar los iconos que se muestran en el header | F2: El usuario no puede visualizar en el menú mis productos la opción de Módulo Regional | G2: Todos-Español SV Idioma Ingles | L2: Cantidad | M2: =COUNTA(G2:G44) -> 43
A3: CP02 | B3: SSO | C3: Validación usuario por Autoafiliación | D3: El usuario debe ser afiliado por medio de Autoadhesión, no por medio de Control Center y Cyberbank | E3: 1.Ingresar el usuario de Banca en línea de HN,PA,CR,SV,CO,MI 2.Seleccionar Empresa a utilizar 3.Ingresar en la posición consolidada 4.Validar los iconos que se muestran en el header ingrese de forma correcta | F3: El usuario no puede visualizar en el menú mis productos la opción de Módulo Regional | G3: Todos-Español SV Idioma Ingles | L3: Colombia | M3: =COUNTIF(G2:G44,"Colombia") -> 9
A4: CP03 | B4: SSO | C4: Ingreso con usuario creado por Control Center | D4: El usuario nuevo debe darse de alta desde CC BEL bajo el procedimiento normal -regulación local. El usuario no debe haberse marcado como usuario Multilatina | E4: 1.Ingresar el usuario de Banca en línea de HN,PA,CR,SV,CO,MI 2.Realiza el proceso de asignación de credenciales 4.Activa el soft token en caso aplique, finalizar el proceso exitoso 3.Ingresar en la posición consolidada | F4: El usuario ingresa las credenciales correctamente e inicia la sesión, al ingresar menú mis productos la opción de Módulo Regional no estará debe ser visible. | G4: Todos-Español SV Idioma Ingles
A5: CP04 | B5: SSO | C5: Ingreso con usuario creado por Cyberbank | D5: El usuario nuevo debe darse de alta desde Cyberbank bajo el procedimiento normal -regulación local. El usuario no debe haberse marcado como usuario Multilatina desde Control Center | E5: 1.Ingresar el usuario de Banca en línea de HN,PA,CR,SV,CO,MI 2.Realiza el proceso de asignación de credenciales 4.Activa el soft token, finalizar el proceso exitoso 3.Ingresar en la posición consolidada | F5: El usuario ingresa las credenciales correctamente e inicia la sesión, al ingresar a la posición consolidada no muestra en la parte superior el icono regional | G5: Todos-Español SV Idioma Ingles
A6: CP05 | B6: SSO | C6: Ingresar con usuario Inactivo-Inhabilitado | D6: El usuario debe estar en un estado diferente a Activo en BEL de su casa Matriz. No debe de estar marcado como usuario Multilatino | E6: 1.Ingresar el usuario de Banca en línea de HN,PA,CR,SV,CO 2.Ingresa las credenciales 3.BEL HN,PA,CR,SV,CO muestra un mensaje correspondiente a la administración de usuario 4. Si permite ingresar validará la posición consolidada 5.No permite ingresar no permitirá visualizar la selección de empresas ni posición consolidada | F6: El usuario no puede visualizar en el menú mis productos la opción de Módulo Regional | G6: Todos-Español SV Idioma Ingles
A7: CP06 | B7: SSO | C7: No debe poseer ningun método de autenticación Usuario Regional | D7: El usuario debe existir en BEL HN,PA,CR,SV El usuario debe tener estado activo Debe estar marcado como usuario multilatino No debe tener activado soft token-Detect ID | E7: 1.Ingresar el usuario de Banca en línea de HN,PA,CR,SV 2.Ingresa las credenciales 3.BEL HN,PA,CR,SV muestra un mensaje correspondiente a la administración de usuario> Según el enumerado de errores correspondiente al Core 4.Visualiza el módulo regional 5.Al realizar el switch al módulo muestra mensaje de Error | F7: El usuario no puede continuar con el proceso ya que es requerido que posea un método de autenticación y se active, en el front debe mostrar un mensaje de Error que le impida ver la posición consolidada. El caso se finaliza cuando muestra el mensaje de Error | G7: Todos-Español SV Idioma Ingles
A8: CP07 | B8: SSO | C8: Usuario Regional No debe permitir ingresar a Módulo Regional | D8: El usuario debe existir en BEL HN,PA,CR,SV Se debe encontrar activo el usuario Debe estar marcado como usuario multilatino Debe tener bloqueado o inactivo el método de autenticación | E8: 1.Ingresar el usuario de Banca en línea de HN,PA,CR,SV 2.Ingresa las credenciales 3.BEL HN,PA,CR,SV muestra un mensaje correspondiente a la administración de usuario 4.Visualiza el módulo regional 5.Ingresa al menú mis productos e ingresa a la opción de Módulo y muestra mensaje “abandonará la banca en línea para acceder al módulo regional” 6.Seleccionar Aceptar | F8: El usuario no puede continuar con el proceso ya que es requerido que posea el soft token y se active, en el front debe mostrar un mensaje de Error que le impida ver la posición consolidada. El caso se finaliza cuando muestra el mensaje de Error | G8: Todos-Español SV Idioma Ingles
A9: CP08 | B9: SSO | C9: Soft Token activo Usuario Regional Finaliza el proceso correctamente y ejecuta el switch al módulo | D9: El usuario debe existir en BEL HN,PA,CR,SV Se debe encontrar activo el usuario Debe estar marcado como cliente y usuario multilatino | E9: 1.Ingresar el usuario de Banca en línea de HN,PA,CR,SV 2.Ingresa las credenciales 3.BEL HN,PA,CR,SV muestra un mensaje correspondiente a la administración de usuario 4.Visualiza el módulo regional 5.Ingresa al menú mis productos y selecciona la opción de Módulo y muestra mensaje “abandonará la banca en línea para acceder al módulo regional” 6.Seleccionar Aceptar | F9: Si el usuario da clic en “aceptar” se debe trasladar los datos de la sesión para el módulo regional y la sesión de BEL quedará activa | G9: Todos-Español SV Idioma Ingles
A10: CP09 | B10: SSO | C10: Token activo Usuario Regional Cancela el switch al módulo | D10: El usuario debe existir en BEL HN,PA,CR,SV Se debe encontrar activo el usuario Debe estar marcado como usuario multilatino | E10: 1.Ingresar el usuario de Banca en línea de HN,PA,CR,SV 2.Ingresa las credenciales 3.BEL HN,PA,CR,SV muestra un mensaje correspondiente a la administración de usuario 4.Visualiza el módulo regional 5.Ingresa al menú mis productos y selecciona la opción de Módulo y muestra mensaje “abandonará la banca en línea para acceder al módulo regional” 6.Seleccionar Aceptar | F10: Si el usuario da clic en “cancelar” cierra el modal y permanece en la banca en línea. Continua la sesión activa en el canal. | G10: Todos-Español SV Idioma Ingles
A11: CP10 | B11: SSO | C11: Cliente Regional Falla en el proceso Por las condiciones de : Usuario Inactivo | D11: El usuario debe existir en BEL HN,PA,CR,SV Se debe encontrar inactivo el usuario Debe estar marcado como usuario multilatino Debe tener una token activo | E11: 1.Ingresar el usuario de Banca en línea de HN,PA,CR,SV 2.Ingresa las credenciales 3.BEL HN,PA,CR,SV muestra un mensaje correspondiente a la administración de usuario | F11: En caso que el canal no pueda confirmar la información ingresada por el usuario se debe presentar mensaje: “Intente más tarde, Por el momento, no es posible atender su solicitud.” | G11: Todos-Español SV Idioma Ingles
A12: CP11 | B12: SSO | C12: Cliente Regional Usuario con Sesión Activa en otro canal (APP locales o Super APP) | D12: El usuario debe existir en BEL HN,PA,CR,SV Se debe encontrar activo el usuario Debe estar marcado como cliente multilatino | E12: 1.Ingresa al App 2. No cierre la sesión 3.Ingresa a Banca en línea pero muestra un mensaje de error | F12: No permite ingresar a BEL debido a que existe una sesión activa Este mensaje dependerá de cada uno de los core si es enviado por correo electrónico o en el front muestra un mensaje de error al usuario. | G12: Todos-Español SV Idioma Ingles
A13: CP12 | B13: SSO | C13: Usuario de Portal realiza el ingreso y permite visualizar el tiempo de sesión Inactiva | D13: El usuario debe existir en BEL HN,PA,CR,SV Se debe encontrar activo el usuario Debe estar marcado como cliente multilatino Token activo | E13: 1.Ingresar el usuario de Banca en línea de HN,PA,CR,SV 2.Ingresa las credenciales 3.BEL HN,PA,CR,SV muestra un mensaje correspondiente a la administración de usuario 4.Visualiza en el menú 'Mis Productos' la opción de módulo regional 5.Ingresa al Módulo y muestra mensaje “abandonará la banca en línea para acceder al módulo regional” 6.Seleccionar Aceptar 7.Ingresa a Selección de Empresas 8.Validar en el header del canal que muestre los siguientes elementos: Nombre del usuario autenticado Rol Cambio de Idioma Ir a Banca Local Cerrar sesión | F13: En caso que no exista ninguna interacción y el límite del contador llegué a cero se presentará el mensaje: “Cerramos la sesión, Por seguridad cerramos esta sesión. Si quiere seguir usando el portal regional, ingrese nuevamente.” ¿Quiere seguir en el portal regional? “La sesión está inactiva y se cerrará en X Segundos, para seguir en el portal diríjase al botón “Continuar” No seleccionar ninguna opción Debe cerrar la sesión debido a inactividad Botón aceptar: Al dar clic en el botón de aceptar se debe informar que la sesión fue expirada. En los escenarios antes mencionados deberán liberar la sesión del usuario para evitar dejar atrapados la sesión. Los usuarios deben recibir notificaciones o confirmaciones por correo electrónico una vez que se haya realizado con éxito un login desde el canal tal cual cómo lo realizan desde la banca en línea o portal empresarial. | G13: Todos-Español SV Idioma Ingles
A14: CP13 | B14: SSO | C14: Usuario de Portal realiza el switch a la Banca Local según el país seleccionado Regresa a la BEL | D14: El usuario debe existir en BEL HN,PA,CR,SV Se debe encontrar activo el usuario Debe estar marcado como usuario multilatino Token activo | E14: 1.Ingresar el usuario de Banca en línea de HN,PA,CR,SV 2.Ingresa las credenciales 3.BEL HN,PA,CR,SV muestra un mensaje correspondiente a la administración de usuario 4.Visualiza el módulo regional 5.Ingresa al Módulo y muestra mensaje “abandonará la banca en línea para acceder al módulo regional” 6.Seleccionar Aceptar 7.Selecciona el botón de regresar a BEL del país indicado | F14: Si el usuario da clic en el botón Regresar a la banca en línea le permitirá cerrar la sesión de Portal y realizar el traslado a la Banca en línea seleccionada. El usuario puede ingresar a BEL-APP y no debe tener la sesión atrapada | G14: Todos-Español SV Idioma Ingles
A15: CP14 | B15: SSO | C15: Usuario de Portal realiza el ingreso y permite visualizar el tiempo de sesión Inactiva cierra la sesión exitosamente por Inactividad | D15: El usuario debe existir en BEL HN,PA,CR,SV Se debe encontrar activo el usuario Debe estar marcado como usuario multilatino | E15: El usuario debe existir en BEL HN,PA,CR,SV Se debe encontrar activo el usuario Debe estar marcado como usuario multilatino | F15: Ingresa a la opción de posición consolidada y muestra deja la sesión inactiva 30 segundos antes muestra un mensaje ¿Quiere seguir en el portal regional? “La sesión está inactiva y se cerrará en X Segundos, para seguir en el portal diríjase al botón “Cerrar sesión” Selecciona cerrar sesión. Al dar clic se cierra el módulo regional y confirma que la sesión fue finalizada exitosamente. No debe existir la sesión activa en BEL | G15: Todos-Español SV Idioma Ingles
... A44: CP43 | B44: SSO | C44: Usuario ingresa a BEL desde el Celular-Iphone - Safari Usuario de Portal realiza el ingreso y permite visualizar el tiempo de sesión Inactiva | D44: El usuario debe existir en BEL CO-MI Se debe encontrar activo el usuario Debe estar marcado como usuario multilatino | E44: 1.Ingresar el usuario de Banca en línea 2.Ingresa las credenciales 3.Muestra un mensaje correspondiente a la administración de usuario 4.Visualiza el módulo regional 5.Ingresa al Módulo y muestra mensaje “abandonará la banca en línea para acceder al módulo regional” 6.Seleccionar Aceptar 7.Ingresa a Posición consolidada | F44: Algunas BEL no tienen responsive por lo que puede variar dependiendo de cada país. Ingresa a la opción de posición consolidada y muestra deja la sesión inactiva 30 segundos antes muestra un mensaje ¿Quiere seguir en el portal regional? “La sesión está inactiva y se cerrará en X Segundos, para seguir en el portal diríjase al botón “Continuar” Selecciona Continuar y realiza logout Los usuarios deben recibir notificaciones o confirmaciones por correo electrónico una vez que se haya realizado con éxito un login desde el canal tal cual cómo lo realizan desde la banca en línea o portal empresarial. | G44: Todos-Español SV Idioma Ingles
C45: Agregar caso de prueba ingresando con holding

Sheet HU002_PER - Home Módulo Regiona
A1: Nomenclatura | B1: Requerimiento | C1: Título | D1: Precondición | E1: Descripción | F1: Resultado | G1: Pais Responsable
A2: CP01 | B2: Home Módulo Regional | C2: Criterio 1 - Home Módulo Regional: Funcionalidades asignadas de cada usuario | D2: Acceder al modulo con usuario autorizante y seleccionar todas las sociedades, el usuario debe estar en estado “activo” y habilitado en el PER | E2: Que el usuario pueda validar las funcionalidades asignadas de acuerdo al rol que posea (Consultor, preparador, aprobador, Administrador.) | F2: El usuario debe de poder visualizar el menu y operar en el modulo Home dependiendo el rol y funcionalidades asignadas | G2: Todos | K2: Consolidado | L2: =COUNTA(G2:G46) -> 45
A3: CP02 | B3: Home Módulo Regional | C3: Criterio 3 - Compatibilidad del ingreso al Modulo Regional | D3: Usuario operador debe de ingresar al modulo regional desde un dispositivo movil con sistema operativo Android | E3: Que el usuario ingrese desde su dispositivo movil Android y navegador google chrome, Se debe de tener consideracion que desde la versión responsive no se debe presentar la sección de accesos rápidos teniendo en cuenta que las funcionalidades transaccionales y administrativas no serán compatibles con dispositivos móviles. | F3: El ingreso a Home Módulo Regional debe de ser exitoso | G3: Todos
A4: CP03 | B4: Home Módulo Regional | C4: Criterio 3 - Compatibilidad del ingreso al Modulo Regional | D4: Usuario autorizante debe de ingresar al modulo regional desde un dispositivo movil con sistema operativo iOS | E4: Que el usuario ingrese desde su dispositivo movil IOS y navegador google chrome, Se debe de tener consideracion que desde la versión responsive no se debe presentar la sección de accesos rápidos teniendo en cuenta que las funcionalidades transaccionales y administrativas no serán compatibles con dispositivos móviles. | F4: El ingreso a Home Módulo Regional debe de ser exitoso | G4: Todos
A5: CP04 | B5: Home Módulo Regional | C5: Criterio 3 - Compatibilidad del ingreso al Modulo Regional | D5: El usuario debe de ingresar al modulo regional desde un dispositivo movil con sistema operativo iOS | E5: Que el usuario ingrese desde su dispositivo movil IOS y navegador zafari, Se debe de tener consideracion que desde la versión responsive no se debe presentar la sección de accesos rápidos teniendo en cuenta que las funcionalidades transaccionales y administrativas no serán compatibles con dispositivos móviles. | F5: El ingreso a Home Módulo Regional debe de ser exitoso | G5: Todos
A6: CP05 | B6: Home Módulo Regional | C6: Criterio 3 - Compatibilidad del ingreso al Modulo Regional | D6: El usuario debe de ingresar al modulo regional desde una tablet con sistema operativo Android | E6: Que el usuario ingrese desde una tablet Android y navegador google chrome | F6: El ingreso a Home Módulo Regional debe de ser exitoso | G6: Todos
A7: CP06 | B7: Home Módulo Regional | C7: Criterio 3 - Compatibilidad del ingreso al Modulo Regional | D7: El usuario debe de ingresar al modulo regional desde una tablet con sistema operativo Android | E7: Que el usuario ingrese desde una tablet IOS y navegador google chrome. | F7: El ingreso a Home Módulo Regional debe de ser exitoso | G7: Todos
A8: CP07 | B8: Home Módulo Regional | C8: Criterio 3 - Compatibilidad del ingreso al Modulo Regional | D8: El usuario debe de ingresar al modulo regional desde una tablet con sistema operativo Android | E8: Que el usuario ingrese desde una tablet IOS y navegador zafari. | F8: El ingreso a Home Módulo Regional debe de ser exitoso | G8: Todos
A9: CP08 | B9: Home Módulo Regional | C9: Criterio 3 - Compatibilidad del ingreso al Modulo Regional | D9: El usuario debe de ingresar al modulo regional desde una computadora de escritorio | E9: Que el usuario ingrese desde una computadora de escritorio el navegador google chrome. | F9: El ingreso a Home Módulo Regional debe de ser exitoso | G9: Todos
A10: CP09 | B10: Home Módulo Regional | C10: Criterio 3 - Compatibilidad del ingreso al Modulo Regional | D10: El usuario debe de ingresar al modulo regional desde una computadora de escritorio | E10: Que el usuario ingrese desde una computadora de escritorio utilizando el navegador Mozilla firefox | F10: El ingreso a Home Módulo Regional debe de ser exitoso | G10: Todos
A11: CP10 | B11: Home Módulo Regional | C11: Criterio 3 - Compatibilidad del ingreso al Modulo Regional | D11: El usuario debe de ingresar al modulo regional desde una computadora de escritorio | E11: Que el usuario ingrese desde una computadora de escritorio utilizando el navegador Edge | F11: El ingreso a Home Módulo Regional debe de ser exitoso | G11: Todos
A12: CP11 | B12: Home Módulo Regional | C12: Criterio 3 - Compatibilidad del ingreso al Modulo Regional | D12: El usuario debe de ingresar al modulo regional desde una computadora de escritorio | E12: Que el usuario ingrese desde una computadora de escritorio utilizando el navegador Explorer | F12: El ingreso a Home Módulo Regional debe de ser exitoso | G12: Todos
A13: CP12 | B13: Home Módulo Regional | C13: Criterio 3 - Compatibilidad del ingreso al Modulo Regional | D13: El usuario debe de ingresar al modulo regional desde una laptop | E13: Que el usuario ingrese desde su laptop utilizando el navegador google chrome. | F13: El ingreso a Home Módulo Regional debe de ser exitoso | G13: Todos
A14: CP13 | B14: Home Módulo Regional | C14: Criterio 3 - Compatibilidad del ingreso al Modulo Regional | D14: El usuario debe de ingresar al modulo regional desde una laptop | E14: Que el usuario ingrese desde su laptop utilizando el navegador Mozilla firefox | F14: El ingreso a Home Módulo Regional debe de ser exitoso | G14: Todos
... A20: CP19 | B20: Home Módulo Regional | C20: "Header" Cambio de idioma | D20: En la barra fija superior derecha se debe de mostrar el icono de cambio de idioma | E20: Validar que al selecconar el icono de cambio de idioma de español a inglés o viceversa sea de manera sencilla. | F20: El cambio de idioma se realice de forma exitosa de acuerdo al seleccionado por el usuario | G20: Todos
A21: CP20 | B21: Home Módulo Regional | C21: "Header" Última conexión / IP | D21: En la parte izquierda inferior se debe de mostrar la ultima conexion | E21: Validar que en la parte inferior se muestre el Último Ingreso y la IP: Ejemplo 11/02/2025 a las 04:08 PM, IP:168.243.173.52 | G21: Todos
A22: CP21 | B22: Home Módulo Regional | C22: "Header" Cerrar sesión | D22: En la barra fija superior se debe de mostrar un icono para cerra sesion | E22: Para el icono de cerrar sesion se deben validar los sigunetes paso: - Sea visible - A l dar click sobre el iconono muestre la pregunta ¿Quiere cerrar la sesión? y mostrará dos opciones “Volver” y "Cerrar sesión”- - Al das clic en “cerrar sesión” finaliza la sesión cerrando las ventanas abiertas - Al click en “Volver” solo cierra la ventana emergente y vuelve a mostrar la pantalla del home. | F22: El icono de cerrar sesion debe de funcinar de forma correcta de acuerdo a la opcion seleccionada | G22: Todos
A23: CP22 | B23: Home Módulo Regional | C23: "Header" Ingresar a la banca local | D23: En la barra fija superior se debe de mostrar un icono que direccione a la banca local | E23: Validar que dar clic en el icono "Banca local" muestre una pantalla con las 5 Opciones ( Colombia, Panamá, Costa Rica, Honduras y El Salvador) - Al seleccionar una de las opciones se cierra la sesion del canal de modulo regional y redirigirá al inicio de sesión del país de la banca local seleccionada | F23: Al seleccionar el pais de ingreso para la banca local, La sesion del modulo regional sea cerrada con exito y el usuario debe volver a autenticarse con los datos de "usuario y clave" personal para acceder al canal. | G23: Todos
A24: CP23 | B24: Home Módulo Regional | C24: Dashboard Home | D24: En el centro de la pantalla se debe de mostrar la información relevante para el usuario | E24: Validar las siguientes funcionalidades: - Empresas Conectadas: Se debe de mostrar un saludo con el nombre del grupo regional ej: “Hola,” Grupo Delpin, de acuerdo a como fue creado en CC - En la parte inferior se debe visualizar el nombre de la empresas que fue seleccionada al inicio de la sesión, y al lado del nombre se debe mostrar la bandera del país al cual pertenece. - Debe tener un elemento como un lápiz para que usuario puede editar la selección de empresas | F24: Que el nombre del grupo de empresa se muestre de forma correcta y el nombre de las empresas seleccionadas se muestre la bandera que corresponde a cada pais | G24: Todos
A25: CP24 | B25: Home Módulo Regional | C25: Dashboard Home "Editar" | D25: En la parte izquierda posterior se debe de mostrar como un lapiz en el que debe aparecer un tooltip con el texto “Editar”. | E25: En la opcion editar al efectuar una modificacion debe de mostrar el mensaje ¿Quiere abandonar esta edición? Si abandona, no se guardarán los cambios realizados. - Debe de permitir realizar búsqueda por país y nombre de acuerdo a las empresas seleccionadas al momento de ingresar al MR - Validar que se encuentren marcadas las casillas de “Checkbox” | F25: Que permita editar en la seleccion de empresas de manera exitosa | G25: Todos
A26: CP25 | B26: Home Módulo Regional | C26: Dashboard Home "Editar" | D26: En la parte izquierda posterior se debe de mostrar como un lapiz en el que debe aparecer un tooltip con el texto “Editar”. | E26: - Validar que al selecionar una nueva empresa se debe de habilitar el botón de “Aceptar”. - Validar que al dar clic en el boton de "Aceptar" si fue actualizada debe de mostrar “marcación exitosa”. si no se realiza mostrará: “Intente más tarde. No pudimos actualizar los cambios”. | F26: Que el boton de aceptar sea habilitado y funcione con exito | G26: Todos
A27: CP26 | B27: Home Módulo Regional | C27: Dashboard Home "Productos" | D27: De acuerdo a la selección de empresas realizadas en el inicio de sesion, el canal debe mostrar una tarjeta en donde se muestre por tipo de productos y “Saldo total consolidado”, para el MVP | E27: Validar que en la tarjeta (en color rojo) se muestre suma del saldo total consolidado de cada producto de acuerdo a lo habilitado de cada empresa - Cuenta ahorros, Corriente y ahorros maestra - El saldo se debe de visulaizar en dólares americanos de acuerdo a los productos asignados y de las empresas con las que el usuario inició sesión. | F27: Quen en la tarjeta roja se mustre el saldo consolidado de de acuerdo a las empresas seleccionadas | G27: Todos
A28: CP27 | B28: Home Módulo Regional | C28: Dashboard Home "Productos" | D28: El canal debe de mostrar los productos cuando el usuario ingrese al módulo regional realizando un llamado único por familias | E28: Cuando el usaurio este en Home se debe de validar que en la tarjeta se muestre el producto con la familia configurada en Control Center con prioridad 1. - Que al dar clic en el detalle se muestre los productos de las demas familias de acuerdo a lo seleccionado | F28: Los productos deben de mostrarse de forma exitosa de acuerdo a alas empresas seleccionadas al hacer login | G28: Todos
A29: CP28 | B29: Home Módulo Regional | C29: Dashboard Home "Tasas de Cambio" | D29: El canal debe mostrar el valor del dólar o tasa de referencia y incluir 2 campos para que el usuario pueda hacer la conversión de moneda local frente al dólar | E29: Validar que en al consultar la tasa de cambio se visualice los siguientes puntos: - Se beben de mostrar 2 campos para hacer la conversión de moneda - La conversion se tomara la del día de la operación - Debe de permitir ingresar valor y el canal debe actualizar de acuerdo a la conversión la equivalencia en la otra moneda.: | F29: Al consultar la tasa de cambio se debe de realizar la conversion de forma exitosa | G29: Todos
A30: CP29 | B30: Home Módulo Regional | C30: Dashboard Home "Accesos Rápidos" | D30: Los usuarios deben tener una opción que permita de acuerdo al rol y permisos sobre las funcionalidades del usuario | E30: Validar que en los acceso directos de acuerdo al rol del usuario permita las siguientes funcionalidades: - Asignar, editar o eliminar accesos a transacciones frecuentes - Al dar clic en unos de los atajos asignados previamente el canal lo debe redirigir a la opción seleccionada | F30: Al ingresar a los accesos rapidos permita editar o eliminar de forma exitosa, a ala vez al acceder a los atajos asignados el canal lo rediriga a la opcion seleccionada sin inconvenientes | G30: Todos
A31: CP30 | B31: Home Módulo Regional | C31: Dashboard Home "Banner expectativa" | D31: El area operativa del Banco pueda subir una imagen alusiva a la funcionalidad o producto del banco que se quiera promocionar | E31: En el canal se podran agregar hasta 5 banner - Se debe validar que se muestre en carrusel - Se debe contar con una flecha que permita cambiar al siguiente banner - Validar que el banner se muestre en un punto visible y que no afecte la vista de los productos del cliente | F31: Si se cuenta con mas de un banner se debe de mostrar una fecha que permita cambiar al siguiente, de forma exitosa | G31: Todos
A32: CP31 | B32: Home Módulo Regional | C32: Sidebar "Menú vertical izquierdo" | D32: Al lado izquierdo se debe de mostrar un menu fijo y en la barra fija superior el lodo de Davivienda | E32: Validar que en el menu izquierdo se muestren los siguientes iconos: - Inicio - Productos - Transferir - Autorizar - Administrar | F32: Que el menu se muestre en vertical al lado izquierdo, con los 5 iconos de forma correcta, | G32: Todos
A33: CP32 | B33: Home Módulo Regional | C33: Sidebar "Menú vertical izquierdo" | D33: El menu se debe de mostrar en forma vertical al lado izquierdo | E33: Validar la funcion de cada icono - Inicio: Al dar clic en este botón debe volver a cargar la pantalla del home o inicio. - Productos: Al dar clic en el botón debe mostrar la información asociada a la historia de usuario de Posición consolidada. Esta funcionalidad está habilitada a los usuarios que tengan la funcionalidad de consultas asignado. - Transferir: Este módulo solo estará habilitado para usuarios que tengan asignada la funcionalidad de “Transferencias Regionales en el MVP” - Autorizar: Esta opción solo estará habilitada para usuarios que tengan el rol de “autorizador” y “Administrador” y a su vez estén en un esquema de firmas. - Administrar: Este módulo solo debe ser visible para los usuarios que tengan perfil de Administrador, al dar clic en esta opción se habilita la opción de “Administrador de módulo regional” en la cual se pueden crear usuarios y grupos de productos. | F33: Cada icono debe de funcionar de forma correcta de acuerdo a la descripcion indicada | G33: Todos
... A46: CP45 | B46: Home Módulo Regional | C46: Logs | D46: Toda interacción que se realice en el módulo de Transferencias debe quedar almacenada para posterior consulta de los usuarios del control Center con el servicio asignado, quienes podrán consultar y visualizar Logs y descarga de informes del Registro completo de cualquier novedad realizada desde el módulo regional, El sistema debe generar y registrar de forma completa y precisa toda la información relacionados con la creación o cualquier novedad realizada, incluyendo toda la información detallada de los datos de entrada y salida, y cualquier error o excepción que se produzca durante el proceso. | E46: Validar que el usuario BO pueda realizar un filtro de busqueda : Fecha de novedad desde - hasta, País, Tipo de novedad | F46: La busqueda de logs debe ser exitosa | G46: Todos

Sheet HU007_PER - Consulta y descarga
A1: Nomenclatura | B1: Requerimiento | C1: Título | D1: Precondición | E1: Descripción | F1: Alcance | G1: Condición | H1: Resultado | I1: Pais Responsable
A2: CP01 | B2: Consulta y descarga de extractos (Estados de cuenta) | C2: Características - Consulta y descarga de extractos (Estados de cuenta) | D2: Ingresar al modulo regional con usuario administrador y seleccionar todas las sociedades, desde la posicion consolidada | E2: Al acceder a esta funcionlidad mientras carga la información que se mostrará en pantalla, se debe mostrar el “Skeleton” py posteriormente se debe de mostar la funcionalidad de "Estados de cuenta " | F2: Validar que se muestren la funionalidad de estados cuenta y que permita al usuario realizar la consulta y opcion de descargarlos | G2: Los productos a los que el usuario puede acceder para autogestionar la consulta y descarga de estados de cuentas (extractos) corresponde únicamente de productos asignados al usuario | H2: La descarga se debe de realizar con exito | I2: Todos | M2: Cantidad de Casos | N2: =SUM(N3:N9) -> 19
A3: CP02 | B3: Consulta y descarga de extractos (Estados de cuenta) | C3: Estados de Cuenta- Consulta y descarga de extractos | D3: Ingresar al modulo regional con usuario Autorizante - y seleccionar todas las sociedades | E3: Seleccionar el boton para realizar la descarga de “Estados de cuenta” al dar clic se actualice la pantalla donde se despliegue las siguientes opciones - Título - Texto - Seleccione la fecha - Formato | F3: El usuario debe de validar que el boton para descargar los estados de cuenta este habilitado | G3: - Los diseños deben adaptarse a una versión responsive. | H3: El boton para descargar los estados cuenta debe de funcionae con exito | I3: Todos | M3: Todos | N3: =COUNTIF(I2:I20,"Todos") -> 7
A4: CP03 | B4: Consulta y descarga de extractos (Estados de cuenta) | C4: Estados de Cuenta- Consulta y descarga de extractos | D4: Ingresar al modulo regional con usuario autorizante - Pais SV | E4: Desde la Posición Consolidada se debe de seleccionar el productos que desea desacargar: - Dar clic en el detalle Producto cuenta de Ahorros o corriente - Dar clic en Estados de cuenta - Se debe de validar que permita realizar una descarga de estado de cuenta de los ultimos 6 meses | F4: Al dar clic en consultar se debe de mostrar : Título: Descarga de estados de cuentas Texto: Si la descarga no se da de inmediato, se debe de mosrtar un mensaje que diga "le enviaremos el archivo al buzón.” Seleccione la fecha: colcoar Año y mes a descargar Formato: PDF Descargar: se debe habilitar el boton para descagar únicamente una vez se haya ingresado al menos el periodo de fecha (MM/AAAA) | G4: - Para el estado de cuenta de El Salvador, solo hace la descarga los últimos 6 meses. - Se debe de tomar en cuenta que para El Salvador solo permite la descarga en PDF Y vendrá seleccionado por Default | H4: La descarga se debe de realizar con exito | I4: El Salvador | M4: El Salvador | N4: =COUNTIF(I2:I20,"El Salvador") -> 2
A5: CP04 | B5: Consulta y descarga de extractos (Estados de cuenta) | C5: Estados de Cuenta- Consulta y descarga de extractos | D5: Ingresar al modulo regional con usuario operador - Pais HN | E5: Desde la Posición Consolidada se debe de seleccionar el productos que desea desacargar: - Dar clic en el detalle Producto cuenta de Ahorros o corriente - Dar clic en Estados de cuenta - Se debe de validar que permita realizar una descarga de estado de cuenta de los ultimos 5 años | F5: Al dar clic en consultar se debe de mostrar : Título: Descarga de estados de cuentas Texto: Si la descarga no se da de inmediato, se debe de mostrar un mesaje que diga "le enviaremos el archivo al buzón.” Seleccione la fecha: colcoar Año y mes a descargar Formato: PDF Descargar: se debe de habilitar únicamente una vez se haya ingresado al menos el periodo de fecha (MM/AAAA) | G5: - Para el estado de cuenta de HN solo hace la descarga los últimos 5 años. - Se debe de tomar en cuenta que para Honduras solo permite la descarga en PDF Y vendrá seleccionado por Default | H5: La descarga se debe de realizar con exito | I5: Honduras | M5: Honduras | N5: =COUNTIF(I2:I21,"Honduras") -> 2
A6: CP05 | B6: Consulta y descarga de extractos (Estados de cuenta) | C6: Estados de Cuenta- Consulta y descarga de extractos | D6: Ingresar al modulo regional con usuario consultor - Pais PA | E6: Desde la Posición Consolidada se debe de seleccionar el productos que desea desacargar: - Dar clic en el detalle Producto cuenta de Ahorros o corriente - Dar clic en Estados de cuenta - Se debe de realizar una descarga de estado de cuenta de uno anterior | F6: Al dar clic en consultar y descargar estado de cuenta se debe de mostrar : Título: Descarga de estados de cuentas Texto: Si la descarga no se da de inmediato, se tiene mostrar un mensaje que diga enviaremos el archivo al buzón.” Seleccione la fecha: se coloca el Año y mes a descargar Formato: PDF Descargar: se debe habilitar el boton de descargar únicamente una vez se haya ingresado al menos el periodo de fecha (MM/AAAA) | G6: - Para el estado de cuenta de Panama, hace la descarga de todos los meses del año actual, y año anterior - Se debe de tomar en cuenta que para Panama solo permite la descarga en PDF Y vendrá seleccionado por Default | H6: La descarga se debe de realizar con exito | I6: Panama | M6: Costa Rica | N6: =COUNTIF(I$2:I22,"Costa Rica") -> 2
A7: CP06 | B7: Consulta y descarga de extractos (Estados de cuenta) | C7: Estados de Cuenta- Consulta y descarga de extractos | D7: Ingresar al modulo regional con usuario autorizante- Pais CR | E7: Desde la Posición Consolidada se debe de seleccionar el productos que desea desacargar: - Dar clic en el detalle Producto cuenta de Ahorros o corriente - Dar clic en Estados de cuenta - Se debe de realizar una descarga de estado de cuenta de los ltimos 5 años | F7: Al dar clic en consultar y descargar estado de cuenta se debe de mostrar : Título: Descarga de estados de cuentas Texto: Si la descarga no se da de inmediato, se tiene mostrar un mensaje que diga enviaremos el archivo al buzón.” Seleccione la fecha: se coloca el Año y mes a descargar Formato: PDF Descargar: se debe habilitar el boton de descargar únicamente una vez se haya ingresado al menos el periodo de fecha (MM/AAAA) | G7: - Para el estado de cuenta de Costa Rica, solo hace la descarga los últimos 5 años. - Se debe de tomar en cuenta que para Costa Rica solo permite la descarga en PDF Y vendrá seleccionado por Default | H7: La descarga se debe de realizar con exito | I7: Costa Rica | M7: Panama | N7: =COUNTIF(I$2:I23,"Panama") -> 2
A8: CP07 | B8: Consulta y descarga de extractos (Estados de cuenta) | C8: Estados de Cuenta- Consulta y descarga de extractos | D8: Ingresar al modulo regional con usuario autorizante- Pais COL | E8: Desde la Posición Consolidada se debe de seleccionar el productos que desea desacargar: - Dar clic en el detalle Producto cuenta de Ahorros o corriente - Dar clic en Estados de cuenta - Se debe de realizar una descarga de estado de cuenta de los ltimos 5 años | F8: Al dar clic en consultar y descargar estado de cuenta se debe de mostrar : Título: Descarga de estados de cuentas Texto: Si la descarga no se da de inmediato, se tiene mostrar un mensaje que diga enviaremos el archivo al buzón.” Seleccione la fecha: se coloca el Año y mes a descargar Formato: PDF Descargar: se debe habilitar el boton de descargar únicamente una vez se haya ingresado al menos el periodo de fecha (MM/AAAA) | G8: - Para el estado de cuenta de Colombia, solo hace la descarga los últimos 5 años. - Se debe de tomar en cuenta que para Colombia debe de permitir la descarga en PDF, Excel (.xlsx) , Plano (.txt) | H8: La descarga se debe de realizar con exito | I8: Colombia | M8: Miami | N8: =COUNTIF(I$2:I24,"Miami") -> 2
A9: CP08 | B9: Consulta y descarga de extractos (Estados de cuenta) | C9: Estados de Cuenta- Consulta y descarga de extractos | D9: Ingresar al modulo regional con usuario autorizante- Pais MIA | E9: Desde la Posición Consolidada se debe de seleccionar el productos que desea desacargar: - Dar clic en el detalle Producto cuenta de Ahorros o corriente - Dar clic en Estados de cuenta - Se debe de realizar una descarga de estado de cuenta de los ltimos 12 meses | F9: Al dar clic en consultar y descargar estado de cuenta se debe de mostrar : Título: Descarga de estados de cuentas Texto: Si la descarga no se da de inmediato, se tiene mostrar un mensaje que diga enviaremos el archivo al buzón.” Seleccione la fecha: se coloca el Año y mes a descargar Formato: PDF Descargar: se debe habilitar el boton de descargar únicamente una vez se haya ingresado al menos el periodo de fecha (MM/AAAA) | G9: - Para el estado de cuenta de Miami, solo hace la descarga los últimos 12 meses - Se debe de tomar en cuenta que para Miami solo permite la descarga en PDF Y vendrá seleccionado por Default | H9: La descarga se debe de realizar con exito | I9: Miami | M9: Colombia | N9: =COUNTIF(I$2:I25,"Colombia") -> 2
A10: CP09 | B10: Consulta y descarga de extractos (Estados de cuenta) | C10: Visualización descarga - Consulta y descarga de extractos | D10: Ingresar al modulo regional con usuario Autorizante - y seleccionar todas las sociedades | E10: Existirán dos formas para visualizar el estado de cuenta una vez el usuario de clic a “Generar” esto dependera del tamaño o rangos de fecha solitados | F10: El usuario debe de realizar una descarga de estado de cuenta con un rango de fecha de un mes atras : Si el tamaño del estado de cuenta permite realizar la descarga en línea, este debe ser generado y el canal debe informar: “Descarga exitosa.” | G10: N/A | H10: La descarga se debe de realizar con exito | I10: Todos
A11: CP10 | B11: Consulta y descarga de extractos (Estados de cuenta) | C11: Visualización descarga - Consulta y descarga de extractos | D11: Ingresar al modulo regional con usuario Operador - y seleccionar todas las sociedades | E11: Existirán dos formas para visualizar el estado de cuenta una vez el usuario de clic a “Generar” esto dependera del tamaño o rangos de fecha solitados | F11: El usuario debe de realizar una descarga de estado de cuenta con un rango de fecha de 3 a 4 meses atras : En caso que el archivo no pueda ser generado inmediatamente se debe de enviar un mensaje temporal que informe: “El estado de cuenta se enviará al buzón de notificaciones del Módulo Regional”, una vez el estado de cuenta sea generado el usuario deberá ingresar al módulo de notificaciones para realizar la descarga del mismo. | G11: N/A | H11: La descarga se debe de realizar con exito | I11: Todos
A12: CP11 | B12: Consulta y descarga de extractos (Estados de cuenta) | C12: Visualización descarga - Consulta y descarga de extractos | D12: Ingresar desde un dispositivo con usuario autorizador / Usuario con aprobacion directa - Pais SV | E12: Realizar la descarga desde un dispositivo con visualización responsiva | F12: Validar que el archivo se descarga al dispositivo se visualice de manera nativa según el dispositivo y sistema operativo. | G12: N/A | H12: La descarga se debe de realizar con exito | I12: El Salvador
A13: CP12 | B13: Consulta y descarga de extractos (Estados de cuenta) | C13: Visualización descarga - Consulta y descarga de extractos | D13: Ingresar desde un dispositivo con usuario autorizador / Usuario con aprobacion directa - Pais PA | E13: Realizar la descarga desde un dispositivo con visualización responsiva | F13: Validar que el archivo se descarga al dispositivo se visualice de manera nativa según el dispositivo y sistema operativo. | G13: N/A | H13: La descarga se debe de realizar con exito | I13: Panama
A14: CP13 | B14: Consulta y descarga de extractos (Estados de cuenta) | C14: Visualización descarga - Consulta y descarga de extractos | D14: Ingresar desde un dispositivo con usuario autorizador / Usuario con aprobacion directa - Pais CR | E14: Realizar la descarga desde un dispositivo con visualización responsiva | F14: Validar que el archivo se descarga al dispositivo se visualice de manera nativa según el dispositivo y sistema operativo. | G14: N/A | H14: La descarga se debe de realizar con exito | I14: Costa Rica
A15: CP14 | B15: Consulta y descarga de extractos (Estados de cuenta) | C15: Visualización descarga - Consulta y descarga de extractos | D15: Ingresar desde un dispositivo con usuario autorizador / Usuario con aprobacion directa - Pais HN | E15: Realizar la descarga desde un dispositivo con visualización responsiva | F15: Validar que el archivo se descarga al dispositivo se visualice de manera nativa según el dispositivo y sistema operativo. | G15: N/A | H15: La descarga se debe de realizar con exito | I15: Honduras
A16: CP15 | B16: Consulta y descarga de extractos (Estados de cuenta) | C16: Visualización descarga - Consulta y descarga de extractos | D16: Ingresar desde un dispositivo con usuario autorizador / Usuario con aprobacion directa - Pais COL | E16: Realizar la descarga desde un dispositivo con visualización responsiva | F16: Validar que el archivo se descarga al dispositivo se visualice de manera nativa según el dispositivo y sistema operativo. | G16: N/A | H16: La descarga se debe de realizar con exito | I16: Colombia
A17: CP16 | B17: Consulta y descarga de extractos (Estados de cuenta) | C17: Visualización descarga - Consulta y descarga de extractos | D17: Ingresar desde un dispositivo con usuario autorizador / Usuario con aprobacion directa - Pais MIA | E17: Realizar la descarga desde un dispositivo con visualización responsiva | F17: Validar que el archivo se descarga al dispositivo se visualice de manera nativa según el dispositivo y sistema operativo. | G17: N/A | H17: La descarga se debe de realizar con exito | I17: Miami
A18: CP17 | B18: Consulta y descarga de extractos (Estados de cuenta) | C18: Consulta y descarga de extractos (Estados de cuenta) / Cambio de idioma | D18: El usuario debe de realizar el proceso de cambio de idioma de español a ingles | E18: Se debe de validar que al realizar el cambio de idioma no afecte los productos que se muestran en la pocion consolidada | F18: El usuario debe de consultar los productos, para validar que se muestre de forma correcta en idioma ingles y los textos del canal deben corresponder | G18: N/A | H18: El cambio de idioma se debe de realizar exitosamente | I18: Todos
A19: CP18 | B19: Consulta y descarga de extractos (Estados de cuenta) | C19: Consulta y descarga de extractos (Estados de cuenta) / Cambio de idioma | D19: El usuario debe de realizar el proceso de cambio de idioma de ingles a español | E19: Se debe de validar que al realizar el cambio de idioma no afecte los productos que se muestran en la pocion consolidada | F19: El usuario debe de consultar los productos, para validar que se muestre de forma correcta en idioma español y los textos del canal deben corresponder | G19: N/A | H19: El cambio de idioma se debe de realizar exitosamente | I19: Todos
A20: CP19 | B20: Consulta y descarga de extractos (Estados de cuenta) | C20: Logs | D20: Toda interacción que se realice en el módulo de Transferencias debe quedar almacenada para posterior consulta de los usuarios del control Center con el servicio asignado, quienes podrán consultar y visualizar Logs y descarga de informes del Registro completo de cualquier novedad realizada desde el módulo regional, El sistema debe generar y registrar de forma completa y precisa toda la información relacionados con la creación o cualquier novedad realizada, incluyendo toda la información detallada de los datos de entrada y salida, y cualquier error o excepción que se produzca durante el proceso. | E20: Validar que el usuario BO pueda realizar un filtro de busqueda : Fecha de novedad desde - hasta, País, Tipo de novedad | F20: N/A | G20: N/A | H20: La busqueda de logs debe ser exitosa | I20: Todos

Sheet HU008_PER - Módulo de administr
A1: not | B1: Requerimiento | C1: Título | D1: Precondición | E1: Descripción | F1: Condición | G1: Resultado | H1: Resultado | I1: Preubas en UAT
A2: CP01 | B2: Usuarios Back Office Control Center- Tech | C2: Validación de Perfiles únicamente de Banca en Línea | D2: Usuario BO ingrese al CC de su banca Local SV-CR-PA-HN | E2: Ingresar Credenciales Exitosas-Permite el acceso Ingresar Credenciales Erroneas- No permite el acceso | F2: Se solicita ejecutar pruebas de no afectación con usuarios BO que no poseen perfiles Regionales | G2: Solamente puede visualizar las empresas Local y como lectura un cliente marcado como multilatino | H2: Todos | L2: Consolidado | M2: =COUNTA(H2:H136) -> 135
A3: CP02 | B3: Usuarios Back Office Control Center -Tech | C3: Validación Marcación Segmento Personas | D3: Cliente existente al segmento de personas no debe mostrar nuevos campos (MVP sí mostrará el campo de 'Cliente módulo Regional') Deben poseer información de clientes existentes para cada uno de los segmentos Usuarios BO a utilizar deben de ser Banca en línea de cada uno de los países | E3: Ingresar a CC CR Ingresar al menú de Administración Clientes Seleccionar Clientes Puede Utilizar los filtros de País, Tipo de Documento, Número de Documento, Nombre Empresa Seleccionar Segmento Personas y/o Pyme Seleccionar Buscar debe mostrar el resultado Seleccionar Detalle de cliente a modificar Debe visualizar los botones Volver-Modificar-Eliminar-Deshabilitar Seleccionar Modificar Mostrará el Campo Cliente Multilatino (MVP sí mostrará el campo de 'Cliente módulo Regional') Los botones a visualizar es Volver y Continuar Seleccionar Volver Visualizará la información del detalle | G3: Efectuar los casos de prueba de no afectación para CC de CR de los segmentos | H3: Todos | J3: CR
A4: CP03 | B4: Usuarios Back Office Control Center - Tech Usuario Operador/Autorizante | C4: Validación usuarios con Perfiles Regionales | D4: Cliente ya debe existir en la Banca Local Seleccionar opción de Modificar la sociedad y seleccionar empresa Local como multilatina Solamente el usuario dominio del país podrá marcar el cliente | E4: Utilizar una empresa dentro del listado indicado Ingresar a CC CR- SV- HN- PA Ingresar al menú de Administración Clientes Seleccionar Clientes Puede Utilizar los filtros de País, Tipo de Documento, Número de Documento, Nombre Empresa Seleccionar Buscar debe mostrar el resultado Seleccionar Detalle de la sociedad a modificar Debe visualizar los botones Volver-Modificar-Eliminar-Deshabilitar Seleccionar Modificar Debe mostrarse el Campo Cliente módulo Regional Seleccionar Continuar Seleccionar en Perfiles Continuar Seleccionar en Confirmar Continuar Finalizar el proceso de la modificación del cliente y debe mostrar un mensaje de pendiente de Autorización | G4: Solicitud se encuentre pendienta de Aprobación en Control Center | H4: Todos
A5: CP04 | B5: Usuarios Back Office Control Center - Tech Autorizante | C5: Validar que la solicitud de autorización del mismo dominio se muestre. | D5: El usuario Autorizante debe tener permiso con perfil Autorizante | E5: Ingresar al CC CR Autorizar la solicitud enviada por el Operador BO o por otro usuario Autorizante del mismo dominio país Ingresar al menú Administración Clientes Seleccionar Clientes Puede Utilizar los filtros de País, Tipo de Documento, Número de Documento, Nombre Empresa Seleccionar Buscar debe mostrar el resultado Seleccionar Detalle de la sociedad a modificar Debe visualizar los botones Volver-Modificar-Eliminar-Deshabilitar No se debe seleccionar ningún botón unicamente es validar que los gestiones se visualicen desde ese menú Ingresar al Menú de Autorizaciones Seleccionar Autorizaciones Pendientes Utilizar los filtros de Usuario - Fecha desde -Fecha Hasta Seleccionar la opción Buscar Debe mostrar el resultado de Solicitud Seleccionar detalle del cliente seleccionado Debe mostrar botones : Volver- Autoriza- Rechazar Seleccionar Autorizar Seleccionar Continuar hasta finalizar el proceso y capturar todas las pantallas del proceso | G5: Autorizar la solicitud de modificación de la empresa | H5: Todos | J5: Dependencia de CR
A6: CP05 | B6: Usuarios Back Office Control Center Usuario Operador/Autorizante | C6: Validación usuarios con Perfiles Regionales | D6: Cliente ya debe existir en la Banca Local Seleccionar opción de Modificar la sociedad y seleccionar empresa Local como multilatina Solamente el usuario dominio del país podrá marcar el cliente | E6: Utilizar una empresa dentro del listado indicado Ingresar a CC Bel Local-SV-PA-HN Ingresar al menú de Administración Clientes Seleccionar Clientes Puede Utilizar los filtros de País, Tipo de Documento, Número de Documento, Nombre Empresa Seleccionar Buscar debe mostrar el resultado Seleccionar Detalle de la sociedad a modificar Debe visualizar los botones Volver-Modificar-Eliminar-Deshabilitar Seleccionar Modificar Debe mostrarse el Campo Cliente Módulo Regional Seleccionar Continuar Seleccionar en Perfiles Continuar Seleccionar en Confirmar Continuar Finalizar el proceso de la modificación del cliente y debe mostrar un mensaje de pendiente de Autorización | G6: Solicitud se encuentre pendiente de Aprobación en Control Center | H6: Alcance | J6: -
A7: CP06 | B7: Usuarios Back Office Control Center Autorizante | C7: Validar que la solicitud de autorización del mismo dominio se muestre | D7: El usuario Autorizante debe tener permiso con perfil Autorizante | E7: Ingresar al CC BEL -SV-PA-HN Autorizar la solicitud enviada por el Operador BO o por otro usuario Autorizante del mismo dominio país Ingresar al menú Administración Clientes Seleccionar Clientes Puede Utilizar los filtros de País, Tipo de Documento, Número de Documento, Nombre Empresa Seleccionar Buscar debe mostrar el resultado, ya sea por la información ingresada en los filtros o sino se han utilizado los filtros debe mostrar infromación de todos los clientes Seleccionar Detalle de la sociedad a modificar Debe visualizar los botones Volver-Modificar-Eliminar-Deshabilitar No se debe seleccionar ningún botón unicamente es validar que los gestiones se visualicen desde ese menú Ingresar al Menú de Autorizaciones Seleccionar Autorizaciones Pendientes Utilizar los filtros de Usuario - Fecha desde -Fecha Hasta Seleccionar la opción Buscar Debe mostrar el resultado de Solicitud Seleccionar detalle del cliente seleccionado Debe mostrar botones : Volver- Autoriza- Rechazar Seleccionar Autorizar Seleccionar Continuar hasta finalizar el proceso y capturar todas las pantallas del proceso | G7: Autorizar la solicitud de modificación de la empresa | H7: Todos
